<?xml version="1.0"?>
<robot xmlns:xacro="http://www.ros.org/wiki/xacro">


    <material name="orange">
        <color rgba="1 0.3 0.1 1" />
    </material>

    <material name="blue">
        <color rgba="0.2 0.2 1 1" />
    </material>

    <material name="black">
        <color rgba="0 0 0 1" />
    </material>

    <material name="red">
        <color rgba="1 0 0 1" />
    </material>

    <material name="white">
        <color rgba="1 1 1 1" />
    </material>



    <!-- BASE LINK -->

    <link name="base_link">

    </link>

    <joint name="base_footprint_joint" type="fixed">
        <parent link="base_link" />
        <child link="base_footprint" />
        <origin xyz="0 0 0" rpy="0 0 0" />
    </joint>

    <joint name="chassis_joint" type="fixed">
        <parent link="base_link" />
        <child link="chassis" />
        <!-- Setting just behind the base_link (center of the motors) TODO: Measure this better -->
        <origin xyz="-0.1 0 0" />
    </joint>

    <!-- CHASSIS LINK -->

    <link name="chassis">
        <visual>
            <!-- We are going 1/2 its length in x and z to move the visuals to where we said it
            should be in the chassis -->
            <origin xyz="0.18 0.0 0.08" rpy="0.0 0.0 0.0" />

            <geometry>
                <box size="0.24 0.24 0.18" />
            </geometry>
            <material name="white" />
        </visual>
        <collision>
            <!-- We are going 1/2 its length in x and z to move the visuals to where we said it
            should be in the chassis -->
            <origin xyz="0.18 0.0 0.08" rpy="0.0 0.0 0.0" />

            <geometry>
                <box size="0.24 0.24 0.16" />
            </geometry>
        </collision>
        <xacro:inertial_box mass="0.5" x="0.24" y="0.24" z="0.16">
            <origin xyz="0.18 0.0 0.08" rpy="0.0 0.0 0.0"/>
        </xacro:inertial_box>
    </link>

    <gazebo reference="chassis">
        <material>
            Gazebo/White   
        </material>
    </gazebo>


    <!-- LEFT WHEEL LINK -->
    <joint name="left_wheel_joint" type="continuous">
        <parent link="base_link" />
        <child link="left_wheel" />
        <origin xyz="0.0 0.126 0.0" rpy="-${pi/2} 0.0 0.0" />
        <axis xyz="0 0 1" />
    </joint>

    <link name="left_wheel">
        <visual>
            <geometry>
                <cylinder radius="0.0325" length="0.026" />
            </geometry>
            <material name="blue" />
        </visual>
        <collision>
            <geometry>
                <cylinder radius="0.0325" length="0.026" />
            </geometry>
        </collision>
        <xacro:inertial_cylinder mass="0.1" length="0.026" radius="0.0325">
            <origin xyz="0.0 0.0 0.0" rpy="0.0 0.0 0.0"/>
        </xacro:inertial_cylinder>
    </link>

    <gazebo reference="left_wheel">
        <material>
            Gazebo/Blue   
        </material>
    </gazebo>

    <!-- RIGHT WHEEL LINK -->
    <joint name="right_wheel_joint" type="continuous">
        <parent link="base_link" />
        <child link="right_wheel" />
        <origin xyz="0.0 -0.126 0.0" rpy="${pi/2} 0.0 0.0" />
        <axis xyz="0 0 -1" />
    </joint>

    <link name="right_wheel">
        <visual>
            <geometry>
                <cylinder radius="0.0325" length="0.026" />
            </geometry>
            <material name="blue" />
        </visual>
        <collision>
            <geometry>
                <cylinder radius="0.0325" length="0.026" />
            </geometry>
        </collision>
        <xacro:inertial_cylinder mass="0.1" length="0.026" radius="0.0325">
            <origin xyz="0.0 0.0 0.0" rpy="0.0 0.0 0.0"/>
        </xacro:inertial_cylinder>
    </link>

    <gazebo reference="right_wheel">
        <material>
            Gazebo/Blue   
        </material>
    </gazebo>

    <!-- CASTER WHEEL LINK -->
    <joint name="caster_wheel_joint" type="fixed">
        <parent link="chassis" />
        <child link="caster_wheel" />
        <origin xyz="0.248 0.0 0.0" rpy="0.0 0.0 0.0" />
    </joint>

    <link name="caster_wheel">
        <visual>
            <geometry>
                <sphere radius="0.03" />
            </geometry>
            <material name="black" />
        </visual>
        <collision>
            <geometry>
                <sphere radius="0.03" />
            </geometry>
        </collision>
        <xacro:inertial_sphere mass="0.1" radius="0.03">
            <origin xyz="0.0 0.0 0.0" rpy="0.0 0.0 0.0"/>
        </xacro:inertial_sphere>
    </link>

    <gazebo reference="caster_wheel">
        <material>
            Gazebo/Black   
        </material>
        <mu1 value="0.001" />
        <mu2 value="0.001" />
    </gazebo>


</robot>